Traceback (most recent call last):
  File "/usr/share/miniconda/envs/text-data/lib/python3.10/site-packages/jupyter_cache/executors/utils.py", line 51, in single_nb_execution
    executenb(
  File "/usr/share/miniconda/envs/text-data/lib/python3.10/site-packages/nbclient/client.py", line 1093, in execute
    return NotebookClient(nb=nb, resources=resources, km=km, **kwargs).execute()
  File "/usr/share/miniconda/envs/text-data/lib/python3.10/site-packages/nbclient/util.py", line 84, in wrapped
    return just_run(coro(*args, **kwargs))
  File "/usr/share/miniconda/envs/text-data/lib/python3.10/site-packages/nbclient/util.py", line 62, in just_run
    return loop.run_until_complete(coro)
  File "/usr/share/miniconda/envs/text-data/lib/python3.10/asyncio/base_events.py", line 641, in run_until_complete
    return future.result()
  File "/usr/share/miniconda/envs/text-data/lib/python3.10/site-packages/nbclient/client.py", line 559, in async_execute
    await self.async_execute_cell(
  File "/usr/share/miniconda/envs/text-data/lib/python3.10/site-packages/nbclient/client.py", line 854, in async_execute_cell
    self._check_raise_for_error(cell, exec_reply)
  File "/usr/share/miniconda/envs/text-data/lib/python3.10/site-packages/nbclient/client.py", line 756, in _check_raise_for_error
    raise CellExecutionError.from_cell_and_msg(cell, exec_reply_content)
nbclient.exceptions.CellExecutionError: An error occurred while executing the following cell:
------------------
# get_url('resources/data/mtg.csv')
# dvc.api.Repo().update()
data_fname = 'resources/data/mtg.csv'
rootdir = Path(dvc.Repo().find_root())


with dvc.open(data_fname) as csv:
    df = pd.read_csv(csv, index_col=0)#.fillna('')

# cards_layout = Layout(pick_fields=['name', 'text', 'flavorText', 'originalText','originalReleaseDate'])
# df = Resource(df, layout=cards_layout).to_pandas()
------------------

[0;31m---------------------------------------------------------------------------[0m
[0;31mNoRemoteError[0m                             Traceback (most recent call last)
[0;32m/usr/share/miniconda/envs/text-data/lib/python3.10/site-packages/dvc/fs/dvc.py[0m in [0;36m_get_fs_path[0;34m(self, path, remote)[0m
[1;32m     85[0m             [0;32mtry[0m[0;34m:[0m[0;34m[0m[0;34m[0m[0m
[0;32m---> 86[0;31m                 [0mremote_odb[0m [0;34m=[0m [0mself[0m[0;34m.[0m[0mrepo[0m[0;34m.[0m[0mcloud[0m[0;34m.[0m[0mget_remote_odb[0m[0;34m([0m[0mremote[0m[0;34m)[0m[0;34m[0m[0;34m[0m[0m
[0m[1;32m     87[0m             [0;32mexcept[0m [0mNoRemoteError[0m [0;32mas[0m [0mexc[0m[0;34m:[0m[0;34m[0m[0;34m[0m[0m

[0;32m/usr/share/miniconda/envs/text-data/lib/python3.10/site-packages/dvc/data_cloud.py[0m in [0;36mget_remote_odb[0;34m(self, name, command)[0m
[1;32m     54[0m [0;34m[0m[0m
[0;32m---> 55[0;31m         [0;32mraise[0m [0mNoRemoteError[0m[0;34m([0m[0merror_msg[0m[0;34m)[0m[0;34m[0m[0;34m[0m[0m
[0m[1;32m     56[0m [0;34m[0m[0m

[0;31mNoRemoteError[0m: config file error: no remote specified. Create a default remote with
    dvc remote add -d <remote name> <remote url>

The above exception was the direct cause of the following exception:

[0;31mFileNotFoundError[0m                         Traceback (most recent call last)
[0;32m/usr/share/miniconda/envs/text-data/lib/python3.10/site-packages/dvc/repo/__init__.py[0m in [0;36mopen_by_relpath[0;34m(self, path, remote, mode, encoding)[0m
[1;32m    494[0m         [0;32mtry[0m[0;34m:[0m[0;34m[0m[0;34m[0m[0m
[0;32m--> 495[0;31m             with fs.open(
[0m[1;32m    496[0m                 [0mpath[0m[0;34m,[0m [0mmode[0m[0;34m=[0m[0mmode[0m[0;34m,[0m [0mencoding[0m[0;34m=[0m[0mencoding[0m[0;34m,[0m [0mremote[0m[0;34m=[0m[0mremote[0m[0;34m[0m[0;34m[0m[0m

[0;32m/usr/share/miniconda/envs/text-data/lib/python3.10/site-packages/dvc/fs/repo.py[0m in [0;36mopen[0;34m(self, path, mode, encoding, **kwargs)[0m
[1;32m    226[0m [0;34m[0m[0m
[0;32m--> 227[0;31m         [0;32mreturn[0m [0mdvc_fs[0m[0;34m.[0m[0mopen[0m[0;34m([0m[0mpath_info[0m[0;34m,[0m [0mmode[0m[0;34m=[0m[0mmode[0m[0;34m,[0m [0mencoding[0m[0;34m=[0m[0mencoding[0m[0;34m,[0m [0;34m**[0m[0mkwargs[0m[0;34m)[0m[0;34m[0m[0;34m[0m[0m
[0m[1;32m    228[0m [0;34m[0m[0m

[0;32m/usr/share/miniconda/envs/text-data/lib/python3.10/site-packages/dvc/fs/dvc.py[0m in [0;36mopen[0;34m(self, path, mode, encoding, **kwargs)[0m
[1;32m    105[0m     ):  # pylint: disable=arguments-renamed
[0;32m--> 106[0;31m         [0mfs[0m[0;34m,[0m [0mfspath[0m [0;34m=[0m [0mself[0m[0;34m.[0m[0m_get_fs_path[0m[0;34m([0m[0mpath[0m[0;34m,[0m [0;34m**[0m[0mkwargs[0m[0;34m)[0m[0;34m[0m[0;34m[0m[0m
[0m[1;32m    107[0m         [0;32mreturn[0m [0mfs[0m[0;34m.[0m[0mopen[0m[0;34m([0m[0mfspath[0m[0;34m,[0m [0mmode[0m[0;34m=[0m[0mmode[0m[0;34m,[0m [0mencoding[0m[0;34m=[0m[0mencoding[0m[0;34m)[0m[0;34m[0m[0;34m[0m[0m

[0;32m/usr/share/miniconda/envs/text-data/lib/python3.10/site-packages/dvc/fs/dvc.py[0m in [0;36m_get_fs_path[0;34m(self, path, remote)[0m
[1;32m     87[0m             [0;32mexcept[0m [0mNoRemoteError[0m [0;32mas[0m [0mexc[0m[0;34m:[0m[0;34m[0m[0;34m[0m[0m
[0;32m---> 88[0;31m                 [0;32mraise[0m [0mFileNotFoundError[0m [0;32mfrom[0m [0mexc[0m[0;34m[0m[0;34m[0m[0m
[0m[1;32m     89[0m             [0;32mif[0m [0mout[0m[0;34m.[0m[0mis_dir_checksum[0m[0;34m:[0m[0;34m[0m[0;34m[0m[0m

[0;31mFileNotFoundError[0m: 

The above exception was the direct cause of the following exception:

[0;31mFileMissingError[0m                          Traceback (most recent call last)
[0;32m/tmp/ipykernel_6375/3593886999.py[0m in [0;36m<module>[0;34m[0m
[1;32m      5[0m [0;34m[0m[0m
[1;32m      6[0m [0;34m[0m[0m
[0;32m----> 7[0;31m [0;32mwith[0m [0mdvc[0m[0;34m.[0m[0mopen[0m[0;34m([0m[0mdata_fname[0m[0;34m)[0m [0;32mas[0m [0mcsv[0m[0;34m:[0m[0;34m[0m[0;34m[0m[0m
[0m[1;32m      8[0m     [0mdf[0m [0;34m=[0m [0mpd[0m[0;34m.[0m[0mread_csv[0m[0;34m([0m[0mcsv[0m[0;34m,[0m [0mindex_col[0m[0;34m=[0m[0;36m0[0m[0;34m)[0m[0;31m#.fillna('')[0m[0;34m[0m[0;34m[0m[0m
[1;32m      9[0m [0;34m[0m[0m

[0;32m/usr/share/miniconda/envs/text-data/lib/python3.10/contextlib.py[0m in [0;36m__enter__[0;34m(self)[0m
[1;32m    133[0m         [0;32mdel[0m [0mself[0m[0;34m.[0m[0margs[0m[0;34m,[0m [0mself[0m[0;34m.[0m[0mkwds[0m[0;34m,[0m [0mself[0m[0;34m.[0m[0mfunc[0m[0;34m[0m[0;34m[0m[0m
[1;32m    134[0m         [0;32mtry[0m[0;34m:[0m[0;34m[0m[0;34m[0m[0m
[0;32m--> 135[0;31m             [0;32mreturn[0m [0mnext[0m[0;34m([0m[0mself[0m[0;34m.[0m[0mgen[0m[0;34m)[0m[0;34m[0m[0;34m[0m[0m
[0m[1;32m    136[0m         [0;32mexcept[0m [0mStopIteration[0m[0;34m:[0m[0;34m[0m[0;34m[0m[0m
[1;32m    137[0m             [0;32mraise[0m [0mRuntimeError[0m[0;34m([0m[0;34m"generator didn't yield"[0m[0;34m)[0m [0;32mfrom[0m [0;32mNone[0m[0;34m[0m[0;34m[0m[0m

[0;32m/usr/share/miniconda/envs/text-data/lib/python3.10/site-packages/dvc/api.py[0m in [0;36m_open[0;34m(path, repo, rev, remote, mode, encoding)[0m
[1;32m     74[0m [0;32mdef[0m [0m_open[0m[0;34m([0m[0mpath[0m[0;34m,[0m [0mrepo[0m[0;34m=[0m[0;32mNone[0m[0;34m,[0m [0mrev[0m[0;34m=[0m[0;32mNone[0m[0;34m,[0m [0mremote[0m[0;34m=[0m[0;32mNone[0m[0;34m,[0m [0mmode[0m[0;34m=[0m[0;34m"r"[0m[0;34m,[0m [0mencoding[0m[0;34m=[0m[0;32mNone[0m[0;34m)[0m[0;34m:[0m[0;34m[0m[0;34m[0m[0m
[1;32m     75[0m     [0;32mwith[0m [0mRepo[0m[0;34m.[0m[0mopen[0m[0;34m([0m[0mrepo[0m[0;34m,[0m [0mrev[0m[0;34m=[0m[0mrev[0m[0;34m,[0m [0msubrepos[0m[0;34m=[0m[0;32mTrue[0m[0;34m,[0m [0muninitialized[0m[0;34m=[0m[0;32mTrue[0m[0;34m)[0m [0;32mas[0m [0m_repo[0m[0;34m:[0m[0;34m[0m[0;34m[0m[0m
[0;32m---> 76[0;31m         with _repo.open_by_relpath(
[0m[1;32m     77[0m             [0mpath[0m[0;34m,[0m [0mremote[0m[0;34m=[0m[0mremote[0m[0;34m,[0m [0mmode[0m[0;34m=[0m[0mmode[0m[0;34m,[0m [0mencoding[0m[0;34m=[0m[0mencoding[0m[0;34m[0m[0;34m[0m[0m
[1;32m     78[0m         ) as fd:

[0;32m/usr/share/miniconda/envs/text-data/lib/python3.10/contextlib.py[0m in [0;36m__enter__[0;34m(self)[0m
[1;32m    133[0m         [0;32mdel[0m [0mself[0m[0;34m.[0m[0margs[0m[0;34m,[0m [0mself[0m[0;34m.[0m[0mkwds[0m[0;34m,[0m [0mself[0m[0;34m.[0m[0mfunc[0m[0;34m[0m[0;34m[0m[0m
[1;32m    134[0m         [0;32mtry[0m[0;34m:[0m[0;34m[0m[0;34m[0m[0m
[0;32m--> 135[0;31m             [0;32mreturn[0m [0mnext[0m[0;34m([0m[0mself[0m[0;34m.[0m[0mgen[0m[0;34m)[0m[0;34m[0m[0;34m[0m[0m
[0m[1;32m    136[0m         [0;32mexcept[0m [0mStopIteration[0m[0;34m:[0m[0;34m[0m[0;34m[0m[0m
[1;32m    137[0m             [0;32mraise[0m [0mRuntimeError[0m[0;34m([0m[0;34m"generator didn't yield"[0m[0;34m)[0m [0;32mfrom[0m [0;32mNone[0m[0;34m[0m[0;34m[0m[0m

[0;32m/usr/share/miniconda/envs/text-data/lib/python3.10/site-packages/dvc/repo/__init__.py[0m in [0;36mopen_by_relpath[0;34m(self, path, remote, mode, encoding)[0m
[1;32m    498[0m                 [0;32myield[0m [0mfobj[0m[0;34m[0m[0;34m[0m[0m
[1;32m    499[0m         [0;32mexcept[0m [0mFileNotFoundError[0m [0;32mas[0m [0mexc[0m[0;34m:[0m[0;34m[0m[0;34m[0m[0m
[0;32m--> 500[0;31m             [0;32mraise[0m [0mFileMissingError[0m[0;34m([0m[0mpath[0m[0;34m)[0m [0;32mfrom[0m [0mexc[0m[0;34m[0m[0;34m[0m[0m
[0m[1;32m    501[0m         [0;32mexcept[0m [0mIsADirectoryError[0m [0;32mas[0m [0mexc[0m[0;34m:[0m[0;34m[0m[0;34m[0m[0m
[1;32m    502[0m             [0;32mraise[0m [0mDvcIsADirectoryError[0m[0;34m([0m[0;34mf"'{path}' is a directory"[0m[0;34m)[0m [0;32mfrom[0m [0mexc[0m[0;34m[0m[0;34m[0m[0m

[0;31mFileMissingError[0m: Can't find '../../../resources/data/mtg.csv' neither locally nor on remote
FileMissingError: Can't find '../../../resources/data/mtg.csv' neither locally nor on remote

