Traceback (most recent call last):
  File "/home/tbsexton/.pyenv/versions/3.10.9/envs/text-data/lib/python3.10/site-packages/jupyter_cache/executors/utils.py", line 58, in single_nb_execution
    executenb(
  File "/home/tbsexton/.pyenv/versions/3.10.9/envs/text-data/lib/python3.10/site-packages/nbclient/client.py", line 1305, in execute
    return NotebookClient(nb=nb, resources=resources, km=km, **kwargs).execute()
  File "/home/tbsexton/.pyenv/versions/3.10.9/envs/text-data/lib/python3.10/site-packages/jupyter_core/utils/__init__.py", line 166, in wrapped
    return loop.run_until_complete(inner)
  File "/home/tbsexton/.pyenv/versions/3.10.9/lib/python3.10/asyncio/base_events.py", line 649, in run_until_complete
    return future.result()
  File "/home/tbsexton/.pyenv/versions/3.10.9/envs/text-data/lib/python3.10/site-packages/nbclient/client.py", line 705, in async_execute
    await self.async_execute_cell(
  File "/home/tbsexton/.pyenv/versions/3.10.9/envs/text-data/lib/python3.10/site-packages/nbclient/client.py", line 1058, in async_execute_cell
    await self._check_raise_for_error(cell, cell_index, exec_reply)
  File "/home/tbsexton/.pyenv/versions/3.10.9/envs/text-data/lib/python3.10/site-packages/nbclient/client.py", line 914, in _check_raise_for_error
    raise CellExecutionError.from_cell_and_msg(cell, exec_reply_content)
nbclient.exceptions.CellExecutionError: An error occurred while executing the following cell:
------------------
from pathlib import Path
import dvc.api as dvc

data_dir = Path(dvc.Repo().find_root())/'resources'/'data'/'shakespeare'/'shakespeare.txt'
------------------


[0;31m---------------------------------------------------------------------------[0m
[0;31mAttributeError[0m                            Traceback (most recent call last)
Cell [0;32mIn[1], line 4[0m
[1;32m      1[0m [38;5;28;01mfrom[39;00m [38;5;21;01mpathlib[39;00m [38;5;28;01mimport[39;00m Path
[1;32m      2[0m [38;5;28;01mimport[39;00m [38;5;21;01mdvc[39;00m[38;5;21;01m.[39;00m[38;5;21;01mapi[39;00m [38;5;28;01mas[39;00m [38;5;21;01mdvc[39;00m
[0;32m----> 4[0m data_dir [38;5;241m=[39m Path([43mdvc[49m[38;5;241;43m.[39;49m[43mRepo[49m()[38;5;241m.[39mfind_root())[38;5;241m/[39m[38;5;124m'[39m[38;5;124mresources[39m[38;5;124m'[39m[38;5;241m/[39m[38;5;124m'[39m[38;5;124mdata[39m[38;5;124m'[39m[38;5;241m/[39m[38;5;124m'[39m[38;5;124mshakespeare[39m[38;5;124m'[39m[38;5;241m/[39m[38;5;124m'[39m[38;5;124mshakespeare.txt[39m[38;5;124m'[39m

[0;31mAttributeError[0m: module 'dvc.api' has no attribute 'Repo'

